Workbook

Sheet Assumptions
A1: Move geometry table: assumptions (blue cells are inputs, change them and every sheet recalculates)
A3: Name | B3: Value | C3: Notes
A4: ANCHOR_CD | B4: 0.5 | C4: Cooldown (s) of the anchor move. Tackle currently has cd 0.5 and PP 35.
A5: ANCHOR_PP | B5: 35 | C5: PP of the anchor move (Tackle).
A6: BETA | B6: 1 | C6: Cooldown exponent: cd = ANCHOR_CD * (ANCHOR_PP / PP)^BETA. 1.0 = pure 1/PP (equal sustained DPS where power x PP is constant). Lower compresses long cooldowns (0.5 = square root).
A7: TAU | B7: 0.5 | C7: Tick interval (s) for continuous kinds in tick mode. Trail already ticks every 0.5 s in the code.
A8: CONE_E | B8: 3 | C8: Decision 2026-10-18: cone divisor = pellets a target takes at TYPICAL range (about 3 for a 7-pellet cone), not the full pellet count.
A9: TRAIL_OVERLAP | B9: 2 | C9: Design overlap: puddles covering a target in the trail. Flame Wheel radius 28 px, move speed about 107 px/s, drop every 0.28 s gives about 1.9.
A10: AURA_TICK_MODE | B10: 1 | C10: 1 = auras deliver the budget as ticks every TAU seconds; 0 = one pulse per cooldown (E = 1). OPEN decision.
A11: PULSE_MAX_CD | B11: 0.8 | C11: Rule of thumb: an aura pulse longer than this reads as a shockwave, not a field around you.
A14: Budget spread (damaging moves only, power units per second per target)
A15: Lowest | B15: =_xlfn.MINIFS(Moves!$T$2:$T$65,Moves!$T$2:$T$65,">0") -> 25.142857 | C15: Budget = power x accuracy x hits / cooldown(PP). A flat budget means PP and power are balanced the way mainline intended; outliers are moves whose PP was balanced by another cost (recoil, recharge, accuracy).
A16: Highest | B16: =_xlfn.MAXIFS(Moves!$T$2:$T$65,Moves!$T$2:$T$65,">0") -> 120
A17: Average | B17: =AVERAGEIF(Moves!$T$2:$T$65,">0") -> 62.358571
A18: Highest / lowest | B18: =B16/B15 -> 4.7727273

Sheet Moves
A1: Move id | B1: Name | C1: Type | D1: Game kind | E1: Workbook kind | F1: Class | G1: Game power | H1: PP | I1: Accuracy | J1: Min hits | K1: Max hits | L1: Base count | M1: Orbit speed (rad/s) | N1: Current cd (s) | O1: Hits per cast | P1: Power x accuracy | Q1: C_cast (power units) | R1: Cooldown from PP (s) | S1: E at base (events per target) | T1: Budget (power units/s per target) | U1: Per-event damage d (power units) | V1: Current single-target potential (power units/s) | W1: New budget / current | X1: New cd / current cd | Y1: Aura check | Z1: Notes
A2: tackle | B2: Tackle | C2: normal | D2: melee | E2: Melee | F2: physical | G2: 40 | H2: 35 | I2: 100 | N2: 0.5 | O2: =IF(AND(J2<>"",K2<>""),(J2+K2)/2,1) -> 1 | P2: =G2*IF(I2="",100,I2)/100 -> 40 | Q2: =P2*O2 -> 40 | R2: =Assumptions!$B$4*(Assumptions!$B$5/H2)^Assumptions!$B$6 -> 0.5 | S2: =IF(D2="cone",MIN(L2,Assumptions!$B$8),IF(D2="orbit",L2*M2/(2*PI())*R2,IF(D2="boomerang",2,IF(D2="aura",IF(Assumptions!$B$10=1,R2/Assumptions!$B$7,1),IF(D2="trail",Assumptions!$B$9*R2/Assumptions!$B$7,1))))) -> 1 | T2: =Q2/R2 -> 80 | U2: =Q2/S2 -> 40 | V2: =IF(D2="cone",G2*L2/N2,IF(D2="orbit",G2*L2*M2/(2*PI()),IF(D2="boomerang",G2*2/N2,IF(D2="projectile",G2*L2/N2,IF(D2="trail",G2*Assumptions!$B$9/0.5,G2/N2))))) -> 80 | W2: =IF(V2=0,"",T2/V2) -> 1 | X2: =R2/N2 -> 1 | Y2: =IF(D2="aura",IF(R2>Assumptions!$B$11,"ticks needed","pulse ok"),"")
A3: quick-attack | B3: Quick Attack | C3: normal | D3: dash | E3: Dash | F3: physical | G3: 40 | H3: 30 | I3: 100 | N3: 0.75 | O3: =IF(AND(J3<>"",K3<>""),(J3+K3)/2,1) -> 1 | P3: =G3*IF(I3="",100,I3)/100 -> 40 | Q3: =P3*O3 -> 40 | R3: =Assumptions!$B$4*(Assumptions!$B$5/H3)^Assumptions!$B$6 -> 0.58333333 | S3: =IF(D3="cone",MIN(L3,Assumptions!$B$8),IF(D3="orbit",L3*M3/(2*PI())*R3,IF(D3="boomerang",2,IF(D3="aura",IF(Assumptions!$B$10=1,R3/Assumptions!$B$7,1),IF(D3="trail",Assumptions!$B$9*R3/Assumptions!$B$7,1))))) -> 1 | T3: =Q3/R3 -> 68.571429 | U3: =Q3/S3 -> 40 | V3: =IF(D3="cone",G3*L3/N3,IF(D3="orbit",G3*L3*M3/(2*PI()),IF(D3="boomerang",G3*2/N3,IF(D3="projectile",G3*L3/N3,IF(D3="trail",G3*Assumptions!$B$9/0.5,G3/N3))))) -> 53.333333 | W3: =IF(V3=0,"",T3/V3) -> 1.2857143 | X3: =R3/N3 -> 0.77777778 | Y3: =IF(D3="aura",IF(R3>Assumptions!$B$11,"ticks needed","pulse ok"),"")
A4: swords-dance | B4: Swords Dance | C4: normal | D4: buff | E4: Buff | F4: status | G4: 0 | H4: 20 | N4: 0.85 | O4: =IF(AND(J4<>"",K4<>""),(J4+K4)/2,1) -> 1 | P4: =G4*IF(I4="",100,I4)/100 -> 0 | Q4: =P4*O4 -> 0 | R4: =Assumptions!$B$4*(Assumptions!$B$5/H4)^Assumptions!$B$6 -> 0.875 | S4: =IF(D4="cone",MIN(L4,Assumptions!$B$8),IF(D4="orbit",L4*M4/(2*PI())*R4,IF(D4="boomerang",2,IF(D4="aura",IF(Assumptions!$B$10=1,R4/Assumptions!$B$7,1),IF(D4="trail",Assumptions!$B$9*R4/Assumptions!$B$7,1))))) -> 1 | T4: =Q4/R4 -> 0 | U4: =Q4/S4 -> 0 | V4: =IF(D4="cone",G4*L4/N4,IF(D4="orbit",G4*L4*M4/(2*PI()),IF(D4="boomerang",G4*2/N4,IF(D4="projectile",G4*L4/N4,IF(D4="trail",G4*Assumptions!$B$9/0.5,G4/N4))))) -> 0 | W4: =IF(V4=0,"",T4/V4) | X4: =R4/N4 -> 1.0294118 | Y4: =IF(D4="aura",IF(R4>Assumptions!$B$11,"ticks needed","pulse ok"),"") | Z4: buff: no damage
A5: agility | B5: Agility | C5: normal | D5: buff | E5: Buff | F5: status | G5: 0 | H5: 30 | N5: 0.85 | O5: =IF(AND(J5<>"",K5<>""),(J5+K5)/2,1) -> 1 | P5: =G5*IF(I5="",100,I5)/100 -> 0 | Q5: =P5*O5 -> 0 | R5: =Assumptions!$B$4*(Assumptions!$B$5/H5)^Assumptions!$B$6 -> 0.58333333 | S5: =IF(D5="cone",MIN(L5,Assumptions!$B$8),IF(D5="orbit",L5*M5/(2*PI())*R5,IF(D5="boomerang",2,IF(D5="aura",IF(Assumptions!$B$10=1,R5/Assumptions!$B$7,1),IF(D5="trail",Assumptions!$B$9*R5/Assumptions!$B$7,1))))) -> 1 | T5: =Q5/R5 -> 0 | U5: =Q5/S5 -> 0 | V5: =IF(D5="cone",G5*L5/N5,IF(D5="orbit",G5*L5*M5/(2*PI()),IF(D5="boomerang",G5*2/N5,IF(D5="projectile",G5*L5/N5,IF(D5="trail",G5*Assumptions!$B$9/0.5,G5/N5))))) -> 0 | W5: =IF(V5=0,"",T5/V5) | X5: =R5/N5 -> 0.68627451 | Y5: =IF(D5="aura",IF(R5>Assumptions!$B$11,"ticks needed","pulse ok"),"") | Z5: buff: no damage
A6: harden | B6: Harden | C6: normal | D6: buff | E6: Buff | F6: status | G6: 0 | H6: 30 | N6: 0.85 | O6: =IF(AND(J6<>"",K6<>""),(J6+K6)/2,1) -> 1 | P6: =G6*IF(I6="",100,I6)/100 -> 0 | Q6: =P6*O6 -> 0 | R6: =Assumptions!$B$4*(Assumptions!$B$5/H6)^Assumptions!$B$6 -> 0.58333333 | S6: =IF(D6="cone",MIN(L6,Assumptions!$B$8),IF(D6="orbit",L6*M6/(2*PI())*R6,IF(D6="boomerang",2,IF(D6="aura",IF(Assumptions!$B$10=1,R6/Assumptions!$B$7,1),IF(D6="trail",Assumptions!$B$9*R6/Assumptions!$B$7,1))))) -> 1 | T6: =Q6/R6 -> 0 | U6: =Q6/S6 -> 0 | V6: =IF(D6="cone",G6*L6/N6,IF(D6="orbit",G6*L6*M6/(2*PI()),IF(D6="boomerang",G6*2/N6,IF(D6="projectile",G6*L6/N6,IF(D6="trail",G6*Assumptions!$B$9/0.5,G6/N6))))) -> 0 | W6: =IF(V6=0,"",T6/V6) | X6: =R6/N6 -> 0.68627451 | Y6: =IF(D6="aura",IF(R6>Assumptions!$B$11,"ticks needed","pulse ok"),"") | Z6: buff: no damage
A7: ember | B7: Ember | C7: fire | D7: projectile | E7: Projectile | F7: special | G7: 40 | H7: 25 | I7: 100 | L7: 1 | N7: 0.52 | O7: =IF(AND(J7<>"",K7<>""),(J7+K7)/2,1) -> 1 | P7: =G7*IF(I7="",100,I7)/100 -> 40 | Q7: =P7*O7 -> 40 | R7: =Assumptions!$B$4*(Assumptions!$B$5/H7)^Assumptions!$B$6 -> 0.7 | S7: =IF(D7="cone",MIN(L7,Assumptions!$B$8),IF(D7="orbit",L7*M7/(2*PI())*R7,IF(D7="boomerang",2,IF(D7="aura",IF(Assumptions!$B$10=1,R7/Assumptions!$B$7,1),IF(D7="trail",Assumptions!$B$9*R7/Assumptions!$B$7,1))))) -> 1 | T7: =Q7/R7 -> 57.142857 | U7: =Q7/S7 -> 40 | V7: =IF(D7="cone",G7*L7/N7,IF(D7="orbit",G7*L7*M7/(2*PI()),IF(D7="boomerang",G7*2/N7,IF(D7="projectile",G7*L7/N7,IF(D7="trail",G7*Assumptions!$B$9/0.5,G7/N7))))) -> 76.923077 | W7: =IF(V7=0,"",T7/V7) -> 0.74285714 | X7: =R7/N7 -> 1.3461538 | Y7: =IF(D7="aura",IF(R7>Assumptions!$B$11,"ticks needed","pulse ok"),"")
A8: flamethrower | B8: Flamethrower | C8: fire | D8: cone | E8: Spray | F8: special | G8: 90 | H8: 15 | I8: 100 | L8: 7 | N8: 0.7 | O8: =IF(AND(J8<>"",K8<>""),(J8+K8)/2,1) -> 1 | P8: =G8*IF(I8="",100,I8)/100 -> 90 | Q8: =P8*O8 -> 90 | R8: =Assumptions!$B$4*(Assumptions!$B$5/H8)^Assumptions!$B$6 -> 1.1666667 | S8: =IF(D8="cone",MIN(L8,Assumptions!$B$8),IF(D8="orbit",L8*M8/(2*PI())*R8,IF(D8="boomerang",2,IF(D8="aura",IF(Assumptions!$B$10=1,R8/Assumptions!$B$7,1),IF(D8="trail",Assumptions!$B$9*R8/Assumptions!$B$7,1))))) -> 3 | T8: =Q8/R8 -> 77.142857 | U8: =Q8/S8 -> 30 | V8: =IF(D8="cone",G8*L8/N8,IF(D8="orbit",G8*L8*M8/(2*PI()),IF(D8="boomerang",G8*2/N8,IF(D8="projectile",G8*L8/N8,IF(D8="trail",G8*Assumptions!$B$9/0.5,G8/N8))))) -> 900 | W8: =IF(V8=0,"",T8/V8) -> 0.085714286 | X8: =R8/N8 -> 1.6666667 | Y8: =IF(D8="aura",IF(R8>Assumptions!$B$11,"ticks needed","pulse ok"),"")
A9: fire-spin | B9: Fire Spin | C9: fire | D9: orbit | E9: Orbit | F9: special | G9: 35 | H9: 15 | I9: 85 | L9: 3 | M9: 2.4 | N9: 0.3 | O9: =IF(AND(J9<>"",K9<>""),(J9+K9)/2,1) -> 1 | P9: =G9*IF(I9="",100,I9)/100 -> 29.75 | Q9: =P9*O9 -> 29.75 | R9: =Assumptions!$B$4*(Assumptions!$B$5/H9)^Assumptions!$B$6 -> 1.1666667 | S9: =IF(D9="cone",MIN(L9,Assumptions!$B$8),IF(D9="orbit",L9*M9/(2*PI())*R9,IF(D9="boomerang",2,IF(D9="aura",IF(Assumptions!$B$10=1,R9/Assumptions!$B$7,1),IF(D9="trail",Assumptions!$B$9*R9/Assumptions!$B$7,1))))) -> 1.3369015 | T9: =Q9/R9 -> 25.5 | U9: =Q9/S9 -> 22.252948 | V9: =IF(D9="cone",G9*L9/N9,IF(D9="orbit",G9*L9*M9/(2*PI()),IF(D9="boomerang",G9*2/N9,IF(D9="projectile",G9*L9/N9,IF(D9="trail",G9*Assumptions!$B$9/0.5,G9/N9))))) -> 40.107046 | W9: =IF(V9=0,"",T9/V9) -> 0.63579851 | X9: =R9/N9 -> 3.8888889 | Y9: =IF(D9="aura",IF(R9>Assumptions!$B$11,"ticks needed","pulse ok"),"")
A10: heat-wave | B10: Heat Wave | C10: fire | D10: nova | E10: Burst | F10: special | G10: 95 | H10: 10 | I10: 90 | L10: 10 | N10: 1.25 | O10: =IF(AND(J10<>"",K10<>""),(J10+K10)/2,1) -> 1 | P10: =G10*IF(I10="",100,I10)/100 -> 85.5 | Q10: =P10*O10 -> 85.5 | R10: =Assumptions!$B$4*(Assumptions!$B$5/H10)^Assumptions!$B$6 -> 1.75 | S10: =IF(D10="cone",MIN(L10,Assumptions!$B$8),IF(D10="orbit",L10*M10/(2*PI())*R10,IF(D10="boomerang",2,IF(D10="aura",IF(Assumptions!$B$10=1,R10/Assumptions!$B$7,1),IF(D10="trail",Assumptions!$B$9*R10/Assumptions!$B$7,1))))) -> 1 | T10: =Q10/R10 -> 48.857143 | U10: =Q10/S10 -> 85.5 | V10: =IF(D10="cone",G10*L10/N10,IF(D10="orbit",G10*L10*M10/(2*PI()),IF(D10="boomerang",G10*2/N10,IF(D10="projectile",G10*L10/N10,IF(D10="trail",G10*Assumptions!$B$9/0.5,G10/N10))))) -> 76 | W10: =IF(V10=0,"",T10/V10) -> 0.64285714 | X10: =R10/N10 -> 1.4 | Y10: =IF(D10="aura",IF(R10>Assumptions!$B$11,"ticks needed","pulse ok"),"")
A11: water-gun | B11: Water Gun | C11: water | D11: projectile | E11: Projectile | F11: special | G11: 40 | H11: 25 | I11: 100 | L11: 1 | N11: 0.44 | O11: =IF(AND(J11<>"",K11<>""),(J11+K11)/2,1) -> 1 | P11: =G11*IF(I11="",100,I11)/100 -> 40 | Q11: =P11*O11 -> 40 | R11: =Assumptions!$B$4*(Assumptions!$B$5/H11)^Assumptions!$B$6 -> 0.7 | S11: =IF(D11="cone",MIN(L11,Assumptions!$B$8),IF(D11="orbit",L11*M11/(2*PI())*R11,IF(D11="boomerang",2,IF(D11="aura",IF(Assumptions!$B$10=1,R11/Assumptions!$B$7,1),IF(D11="trail",Assumptions!$B$9*R11/Assumptions!$B$7,1))))) -> 1 | T11: =Q11/R11 -> 57.142857 | U11: =Q11/S11 -> 40 | V11: =IF(D11="cone",G11*L11/N11,IF(D11="orbit",G11*L11*M11/(2*PI()),IF(D11="boomerang",G11*2/N11,IF(D11="projectile",G11*L11/N11,IF(D11="trail",G11*Assumptions!$B$9/0.5,G11/N11))))) -> 90.909091 | W11: =IF(V11=0,"",T11/V11) -> 0.62857143 | X11: =R11/N11 -> 1.5909091 | Y11: =IF(D11="aura",IF(R11>Assumptions!$B$11,"ticks needed","pulse ok"),"")
A12: bubble | B12: Bubble | C12: water | D12: nova | E12: Burst | F12: special | G12: 40 | H12: 30 | I12: 100 | L12: 8 | N12: 1 | O12: =IF(AND(J12<>"",K12<>""),(J12+K12)/2,1) -> 1 | P12: =G12*IF(I12="",100,I12)/100 -> 40 | Q12: =P12*O12 -> 40 | R12: =Assumptions!$B$4*(Assumptions!$B$5/H12)^Assumptions!$B$6 -> 0.58333333 | S12: =IF(D12="cone",MIN(L12,Assumptions!$B$8),IF(D12="orbit",L12*M12/(2*PI())*R12,IF(D12="boomerang",2,IF(D12="aura",IF(Assumptions!$B$10=1,R12/Assumptions!$B$7,1),IF(D12="trail",Assumptions!$B$9*R12/Assumptions!$B$7,1))))) -> 1 | T12: =Q12/R12 -> 68.571429 | U12: =Q12/S12 -> 40 | V12: =IF(D12="cone",G12*L12/N12,IF(D12="orbit",G12*L12*M12/(2*PI()),IF(D12="boomerang",G12*2/N12,IF(D12="projectile",G12*L12/N12,IF(D12="trail",G12*Assumptions!$B$9/0.5,G12/N12))))) -> 40 | W12: =IF(V12=0,"",T12/V12) -> 1.7142857 | X12: =R12/N12 -> 0.58333333 | Y12: =IF(D12="aura",IF(R12>Assumptions!$B$11,"ticks needed","pulse ok"),"")
A13: hydro-pump | B13: Hydro Pump | C13: water | D13: beam | E13: Beam | F13: special | G13: 110 | H13: 5 | I13: 80 | N13: 1.5 | O13: =IF(AND(J13<>"",K13<>""),(J13+K13)/2,1) -> 1 | P13: =G13*IF(I13="",100,I13)/100 -> 88 | Q13: =P13*O13 -> 88 | R13: =Assumptions!$B$4*(Assumptions!$B$5/H13)^Assumptions!$B$6 -> 3.5 | S13: =IF(D13="cone",MIN(L13,Assumptions!$B$8),IF(D13="orbit",L13*M13/(2*PI())*R13,IF(D13="boomerang",2,IF(D13="aura",IF(Assumptions!$B$10=1,R13/Assumptions!$B$7,1),IF(D13="trail",Assumptions!$B$9*R13/Assumptions!$B$7,1))))) -> 1 | T13: =Q13/R13 -> 25.142857 | U13: =Q13/S13 -> 88 | V13: =IF(D13="cone",G13*L13/N13,IF(D13="orbit",G13*L13*M13/(2*PI()),IF(D13="boomerang",G13*2/N13,IF(D13="projectile",G13*L13/N13,IF(D13="trail",G13*Assumptions!$B$9/0.5,G13/N13))))) -> 73.333333 | W13: =IF(V13=0,"",T13/V13) -> 0.34285714 | X13: =R13/N13 -> 2.3333333 | Y13: =IF(D13="aura",IF(R13>Assumptions!$B$11,"ticks needed","pulse ok"),"")
A14: aqua-ring | B14: Aqua Ring | C14: water | D14: buff | E14: Buff | F14: status | G14: 0 | H14: 20 | N14: 0.9 | O14: =IF(AND(J14<>"",K14<>""),(J14+K14)/2,1) -> 1 | P14: =G14*IF(I14="",100,I14)/100 -> 0 | Q14: =P14*O14 -> 0 | R14: =Assumptions!$B$4*(Assumptions!$B$5/H14)^Assumptions!$B$6 -> 0.875 | S14: =IF(D14="cone",MIN(L14,Assumptions!$B$8),IF(D14="orbit",L14*M14/(2*PI())*R14,IF(D14="boomerang",2,IF(D14="aura",IF(Assumptions!$B$10=1,R14/Assumptions!$B$7,1),IF(D14="trail",Assumptions!$B$9*R14/Assumptions!$B$7,1))))) -> 1 | T14: =Q14/R14 -> 0 | U14: =Q14/S14 -> 0 | V14: =IF(D14="cone",G14*L14/N14,IF(D14="orbit",G14*L14*M14/(2*PI()),IF(D14="boomerang",G14*2/N14,IF(D14="projectile",G14*L14/N14,IF(D14="trail",G14*Assumptions!$B$9/0.5,G14/N14))))) -> 0 | W14: =IF(V14=0,"",T14/V14) | X14: =R14/N14 -> 0.97222222 | Y14: =IF(D14="aura",IF(R14>Assumptions!$B$11,"ticks needed","pulse ok"),"") | Z14: buff: no damage
A15: vine-whip | B15: Vine Whip | C15: grass | D15: melee | E15: Melee | F15: physical | G15: 45 | H15: 25 | I15: 100 | N15: 0.62 | O15: =IF(AND(J15<>"",K15<>""),(J15+K15)/2,1) -> 1 | P15: =G15*IF(I15="",100,I15)/100 -> 45 | Q15: =P15*O15 -> 45 | R15: =Assumptions!$B$4*(Assumptions!$B$5/H15)^Assumptions!$B$6 -> 0.7 | S15: =IF(D15="cone",MIN(L15,Assumptions!$B$8),IF(D15="orbit",L15*M15/(2*PI())*R15,IF(D15="boomerang",2,IF(D15="aura",IF(Assumptions!$B$10=1,R15/Assumptions!$B$7,1),IF(D15="trail",Assumptions!$B$9*R15/Assumptions!$B$7,1))))) -> 1 | T15: =Q15/R15 -> 64.285714 | U15: =Q15/S15 -> 45 | V15: =IF(D15="cone",G15*L15/N15,IF(D15="orbit",G15*L15*M15/(2*PI()),IF(D15="boomerang",G15*2/N15,IF(D15="projectile",G15*L15/N15,IF(D15="trail",G15*Assumptions!$B$9/0.5,G15/N15))))) -> 72.580645 | W15: =IF(V15=0,"",T15/V15) -> 0.88571429 | X15: =R15/N15 -> 1.1290323 | Y15: =IF(D15="aura",IF(R15>Assumptions!$B$11,"ticks needed","pulse ok"),"")
A16: razor-leaf | B16: Razor Leaf | C16: grass | D16: boomerang | E16: Boomerang | F16: physical | G16: 55 | H16: 25 | I16: 95 | L16: 2 | N16: 0.9 | O16: =IF(AND(J16<>"",K16<>""),(J16+K16)/2,1) -> 1 | P16: =G16*IF(I16="",100,I16)/100 -> 52.25 | Q16: =P16*O16 -> 52.25 | R16: =Assumptions!$B$4*(Assumptions!$B$5/H16)^Assumptions!$B$6 -> 0.7 | S16: =IF(D16="cone",MIN(L16,Assumptions!$B$8),IF(D16="orbit",L16*M16/(2*PI())*R16,IF(D16="boomerang",2,IF(D16="aura",IF(Assumptions!$B$10=1,R16/Assumptions!$B$7,1),IF(D16="trail",Assumptions!$B$9*R16/Assumptions!$B$7,1))))) -> 2 | T16: =Q16/R16 -> 74.642857 | U16: =Q16/S16 -> 26.125 | V16: =IF(D16="cone",G16*L16/N16,IF(D16="orbit",G16*L16*M16/(2*PI()),IF(D16="boomerang",G16*2/N16,IF(D16="projectile",G16*L16/N16,IF(D16="trail",G16*Assumptions!$B$9/0.5,G16/N16))))) -> 122.22222 | W16: =IF(V16=0,"",T16/V16) -> 0.61071429 | X16: =R16/N16 -> 0.77777778 | Y16: =IF(D16="aura",IF(R16>Assumptions!$B$11,"ticks needed","pulse ok"),"") | Z16: visual 2-hit (out and back): E = 2 so damage splits across both passes
A17: leaf-storm | B17: Leaf Storm | C17: grass | D17: orbit | E17: Orbit | F17: special | G17: 130 | H17: 5 | I17: 90 | L17: 4 | M17: 2.6 | N17: 0.26 | O17: =IF(AND(J17<>"",K17<>""),(J17+K17)/2,1) -> 1 | P17: =G17*IF(I17="",100,I17)/100 -> 117 | Q17: =P17*O17 -> 117 | R17: =Assumptions!$B$4*(Assumptions!$B$5/H17)^Assumptions!$B$6 -> 3.5 | S17: =IF(D17="cone",MIN(L17,Assumptions!$B$8),IF(D17="orbit",L17*M17/(2*PI())*R17,IF(D17="boomerang",2,IF(D17="aura",IF(Assumptions!$B$10=1,R17/Assumptions!$B$7,1),IF(D17="trail",Assumptions!$B$9*R17/Assumptions!$B$7,1))))) -> 5.7932399 | T17: =Q17/R17 -> 33.428571 | U17: =Q17/S17 -> 20.195953 | V17: =IF(D17="cone",G17*L17/N17,IF(D17="orbit",G17*L17*M17/(2*PI()),IF(D17="boomerang",G17*2/N17,IF(D17="projectile",G17*L17/N17,IF(D17="trail",G17*Assumptions!$B$9/0.5,G17/N17))))) -> 215.17748 | W17: =IF(V17=0,"",T17/V17) -> 0.15535348 | X17: =R17/N17 -> 13.461538 | Y17: =IF(D17="aura",IF(R17>Assumptions!$B$11,"ticks needed","pulse ok"),"")
A18: giga-drain | B18: Giga Drain | C18: grass | D18: aura | E18: Aura | F18: special | G18: 75 | H18: 10 | I18: 100 | N18: 0.55 | O18: =IF(AND(J18<>"",K18<>""),(J18+K18)/2,1) -> 1 | P18: =G18*IF(I18="",100,I18)/100 -> 75 | Q18: =P18*O18 -> 75 | R18: =Assumptions!$B$4*(Assumptions!$B$5/H18)^Assumptions!$B$6 -> 1.75 | S18: =IF(D18="cone",MIN(L18,Assumptions!$B$8),IF(D18="orbit",L18*M18/(2*PI())*R18,IF(D18="boomerang",2,IF(D18="aura",IF(Assumptions!$B$10=1,R18/Assumptions!$B$7,1),IF(D18="trail",Assumptions!$B$9*R18/Assumptions!$B$7,1))))) -> 3.5 | T18: =Q18/R18 -> 42.857143 | U18: =Q18/S18 -> 21.428571 | V18: =IF(D18="cone",G18*L18/N18,IF(D18="orbit",G18*L18*M18/(2*PI()),IF(D18="boomerang",G18*2/N18,IF(D18="projectile",G18*L18/N18,IF(D18="trail",G18*Assumptions!$B$9/0.5,G18/N18))))) -> 136.36364 | W18: =IF(V18=0,"",T18/V18) -> 0.31428571 | X18: =R18/N18 -> 3.1818182 | Y18: =IF(D18="aura",IF(R18>Assumptions!$B$11,"ticks needed","pulse ok"),"") -> ticks needed
A19: thunder-shock | B19: Thunder Shock | C19: electric | D19: projectile | E19: Projectile | F19: special | G19: 40 | H19: 30 | I19: 100 | L19: 1 | N19: 0.4 | O19: =IF(AND(J19<>"",K19<>""),(J19+K19)/2,1) -> 1 | P19: =G19*IF(I19="",100,I19)/100 -> 40 | Q19: =P19*O19 -> 40 | R19: =Assumptions!$B$4*(Assumptions!$B$5/H19)^Assumptions!$B$6 -> 0.58333333 | S19: =IF(D19="cone",MIN(L19,Assumptions!$B$8),IF(D19="orbit",L19*M19/(2*PI())*R19,IF(D19="boomerang",2,IF(D19="aura",IF(Assumptions!$B$10=1,R19/Assumptions!$B$7,1),IF(D19="trail",Assumptions!$B$9*R19/Assumptions!$B$7,1))))) -> 1 | T19: =Q19/R19 -> 68.571429 | U19: =Q19/S19 -> 40 | V19: =IF(D19="cone",G19*L19/N19,IF(D19="orbit",G19*L19*M19/(2*PI()),IF(D19="boomerang",G19*2/N19,IF(D19="projectile",G19*L19/N19,IF(D19="trail",G19*Assumptions!$B$9/0.5,G19/N19))))) -> 100 | W19: =IF(V19=0,"",T19/V19) -> 0.68571429 | X19: =R19/N19 -> 1.4583333 | Y19: =IF(D19="aura",IF(R19>Assumptions!$B$11,"ticks needed","pulse ok"),"")
A20: discharge | B20: Discharge | C20: electric | D20: aura | E20: Aura | F20: special | G20: 80 | H20: 15 | I20: 100 | N20: 0.45 | O20: =IF(AND(J20<>"",K20<>""),(J20+K20)/2,1) -> 1 | P20: =G20*IF(I20="",100,I20)/100 -> 80 | Q20: =P20*O20 -> 80 | R20: =Assumptions!$B$4*(Assumptions!$B$5/H20)^Assumptions!$B$6 -> 1.1666667 | S20: =IF(D20="cone",MIN(L20,Assumptions!$B$8),IF(D20="orbit",L20*M20/(2*PI())*R20,IF(D20="boomerang",2,IF(D20="aura",IF(Assumptions!$B$10=1,R20/Assumptions!$B$7,1),IF(D20="trail",Assumptions!$B$9*R20/Assumptions!$B$7,1))))) -> 2.3333333 | T20: =Q20/R20 -> 68.571429 | U20: =Q20/S20 -> 34.285714 | V20: =IF(D20="cone",G20*L20/N20,IF(D20="orbit",G20*L20*M20/(2*PI()),IF(D20="boomerang",G20*2/N20,IF(D20="projectile",G20*L20/N20,IF(D20="trail",G20*Assumptions!$B$9/0.5,G20/N20))))) -> 177.77778 | W20: =IF(V20=0,"",T20/V20) -> 0.38571429 | X20: =R20/N20 -> 2.5925926 | Y20: =IF(D20="aura",IF(R20>Assumptions!$B$11,"ticks needed","pulse ok"),"") -> ticks needed
A21: thunderbolt | B21: Thunderbolt | C21: electric | D21: chain | E21: Chain | F21: special | G21: 90 | H21: 15 | I21: 100 | L21: 4 | N21: 0.95 | O21: =IF(AND(J21<>"",K21<>""),(J21+K21)/2,1) -> 1 | P21: =G21*IF(I21="",100,I21)/100 -> 90 | Q21: =P21*O21 -> 90 | R21: =Assumptions!$B$4*(Assumptions!$B$5/H21)^Assumptions!$B$6 -> 1.1666667 | S21: =IF(D21="cone",MIN(L21,Assumptions!$B$8),IF(D21="orbit",L21*M21/(2*PI())*R21,IF(D21="boomerang",2,IF(D21="aura",IF(Assumptions!$B$10=1,R21/Assumptions!$B$7,1),IF(D21="trail",Assumptions!$B$9*R21/Assumptions!$B$7,1))))) -> 1 | T21: =Q21/R21 -> 77.142857 | U21: =Q21/S21 -> 90 | V21: =IF(D21="cone",G21*L21/N21,IF(D21="orbit",G21*L21*M21/(2*PI()),IF(D21="boomerang",G21*2/N21,IF(D21="projectile",G21*L21/N21,IF(D21="trail",G21*Assumptions!$B$9/0.5,G21/N21))))) -> 94.736842 | W21: =IF(V21=0,"",T21/V21) -> 0.81428571 | X21: =R21/N21 -> 1.2280702 | Y21: =IF(D21="aura",IF(R21>Assumptions!$B$11,"ticks needed","pulse ok"),"")
A22: confusion | B22: Confusion | C22: psychic | D22: projectile | E22: Projectile | F22: special | G22: 50 | H22: 25 | I22: 100 | L22: 1 | N22: 0.58 | O22: =IF(AND(J22<>"",K22<>""),(J22+K22)/2,1) -> 1 | P22: =G22*IF(I22="",100,I22)/100 -> 50 | Q22: =P22*O22 -> 50 | R22: =Assumptions!$B$4*(Assumptions!$B$5/H22)^Assumptions!$B$6 -> 0.7 | S22: =IF(D22="cone",MIN(L22,Assumptions!$B$8),IF(D22="orbit",L22*M22/(2*PI())*R22,IF(D22="boomerang",2,IF(D22="aura",IF(Assumptions!$B$10=1,R22/Assumptions!$B$7,1),IF(D22="trail",Assumptions!$B$9*R22/Assumptions!$B$7,1))))) -> 1 | T22: =Q22/R22 -> 71.428571 | U22: =Q22/S22 -> 50 | V22: =IF(D22="cone",G22*L22/N22,IF(D22="orbit",G22*L22*M22/(2*PI()),IF(D22="boomerang",G22*2/N22,IF(D22="projectile",G22*L22/N22,IF(D22="trail",G22*Assumptions!$B$9/0.5,G22/N22))))) -> 86.206897 | W22: =IF(V22=0,"",T22/V22) -> 0.82857143 | X22: =R22/N22 -> 1.2068966 | Y22: =IF(D22="aura",IF(R22>Assumptions!$B$11,"ticks needed","pulse ok"),"")
A23: psybeam | B23: Psybeam | C23: psychic | D23: beam | E23: Beam | F23: special | G23: 65 | H23: 20 | I23: 100 | N23: 1.15 | O23: =IF(AND(J23<>"",K23<>""),(J23+K23)/2,1) -> 1 | P23: =G23*IF(I23="",100,I23)/100 -> 65 | Q23: =P23*O23 -> 65 | R23: =Assumptions!$B$4*(Assumptions!$B$5/H23)^Assumptions!$B$6 -> 0.875 | S23: =IF(D23="cone",MIN(L23,Assumptions!$B$8),IF(D23="orbit",L23*M23/(2*PI())*R23,IF(D23="boomerang",2,IF(D23="aura",IF(Assumptions!$B$10=1,R23/Assumptions!$B$7,1),IF(D23="trail",Assumptions!$B$9*R23/Assumptions!$B$7,1))))) -> 1 | T23: =Q23/R23 -> 74.285714 | U23: =Q23/S23 -> 65 | V23: =IF(D23="cone",G23*L23/N23,IF(D23="orbit",G23*L23*M23/(2*PI()),IF(D23="boomerang",G23*2/N23,IF(D23="projectile",G23*L23/N23,IF(D23="trail",G23*Assumptions!$B$9/0.5,G23/N23))))) -> 56.521739 | W23: =IF(V23=0,"",T23/V23) -> 1.3142857 | X23: =R23/N23 -> 0.76086957 | Y23: =IF(D23="aura",IF(R23>Assumptions!$B$11,"ticks needed","pulse ok"),"")
A24: psychic | B24: Psychic | C24: psychic | D24: nova | E24: Burst | F24: special | G24: 90 | H24: 10 | I24: 100 | L24: 12 | N24: 1.35 | O24: =IF(AND(J24<>"",K24<>""),(J24+K24)/2,1) -> 1 | P24: =G24*IF(I24="",100,I24)/100 -> 90 | Q24: =P24*O24 -> 90 | R24: =Assumptions!$B$4*(Assumptions!$B$5/H24)^Assumptions!$B$6 -> 1.75 | S24: =IF(D24="cone",MIN(L24,Assumptions!$B$8),IF(D24="orbit",L24*M24/(2*PI())*R24,IF(D24="boomerang",2,IF(D24="aura",IF(Assumptions!$B$10=1,R24/Assumptions!$B$7,1),IF(D24="trail",Assumptions!$B$9*R24/Assumptions!$B$7,1))))) -> 1 | T24: =Q24/R24 -> 51.428571 | U24: =Q24/S24 -> 90 | V24: =IF(D24="cone",G24*L24/N24,IF(D24="orbit",G24*L24*M24/(2*PI()),IF(D24="boomerang",G24*2/N24,IF(D24="projectile",G24*L24/N24,IF(D24="trail",G24*Assumptions!$B$9/0.5,G24/N24))))) -> 66.666667 | W24: =IF(V24=0,"",T24/V24) -> 0.77142857 | X24: =R24/N24 -> 1.2962963 | Y24: =IF(D24="aura",IF(R24>Assumptions!$B$11,"ticks needed","pulse ok"),"")
A25: sludge | B25: Sludge | C25: poison | D25: projectile | E25: Projectile | F25: special | G25: 65 | H25: 20 | I25: 100 | L25: 1 | N25: 0.6 | O25: =IF(AND(J25<>"",K25<>""),(J25+K25)/2,1) -> 1 | P25: =G25*IF(I25="",100,I25)/100 -> 65 | Q25: =P25*O25 -> 65 | R25: =Assumptions!$B$4*(Assumptions!$B$5/H25)^Assumptions!$B$6 -> 0.875 | S25: =IF(D25="cone",MIN(L25,Assumptions!$B$8),IF(D25="orbit",L25*M25/(2*PI())*R25,IF(D25="boomerang",2,IF(D25="aura",IF(Assumptions!$B$10=1,R25/Assumptions!$B$7,1),IF(D25="trail",Assumptions!$B$9*R25/Assumptions!$B$7,1))))) -> 1 | T25: =Q25/R25 -> 74.285714 | U25: =Q25/S25 -> 65 | V25: =IF(D25="cone",G25*L25/N25,IF(D25="orbit",G25*L25*M25/(2*PI()),IF(D25="boomerang",G25*2/N25,IF(D25="projectile",G25*L25/N25,IF(D25="trail",G25*Assumptions!$B$9/0.5,G25/N25))))) -> 108.33333 | W25: =IF(V25=0,"",T25/V25) -> 0.68571429 | X25: =R25/N25 -> 1.4583333 | Y25: =IF(D25="aura",IF(R25>Assumptions!$B$11,"ticks needed","pulse ok"),"")
A26: mud-shot | B26: Mud Shot | C26: ground | D26: nova | E26: Burst | F26: special | G26: 55 | H26: 15 | I26: 95 | L26: 7 | N26: 1.1 | O26: =IF(AND(J26<>"",K26<>""),(J26+K26)/2,1) -> 1 | P26: =G26*IF(I26="",100,I26)/100 -> 52.25 | Q26: =P26*O26 -> 52.25 | R26: =Assumptions!$B$4*(Assumptions!$B$5/H26)^Assumptions!$B$6 -> 1.1666667 | S26: =IF(D26="cone",MIN(L26,Assumptions!$B$8),IF(D26="orbit",L26*M26/(2*PI())*R26,IF(D26="boomerang",2,IF(D26="aura",IF(Assumptions!$B$10=1,R26/Assumptions!$B$7,1),IF(D26="trail",Assumptions!$B$9*R26/Assumptions!$B$7,1))))) -> 1 | T26: =Q26/R26 -> 44.785714 | U26: =Q26/S26 -> 52.25 | V26: =IF(D26="cone",G26*L26/N26,IF(D26="orbit",G26*L26*M26/(2*PI()),IF(D26="boomerang",G26*2/N26,IF(D26="projectile",G26*L26/N26,IF(D26="trail",G26*Assumptions!$B$9/0.5,G26/N26))))) -> 50 | W26: =IF(V26=0,"",T26/V26) -> 0.89571429 | X26: =R26/N26 -> 1.0606061 | Y26: =IF(D26="aura",IF(R26>Assumptions!$B$11,"ticks needed","pulse ok"),"")
A27: gust | B27: Gust | C27: flying | D27: orbit | E27: Orbit | F27: special | G27: 40 | H27: 35 | I27: 100 | L27: 3 | M27: 2.8 | N27: 0.26 | O27: =IF(AND(J27<>"",K27<>""),(J27+K27)/2,1) -> 1 | P27: =G27*IF(I27="",100,I27)/100 -> 40 | Q27: =P27*O27 -> 40 | R27: =Assumptions!$B$4*(Assumptions!$B$5/H27)^Assumptions!$B$6 -> 0.5 | S27: =IF(D27="cone",MIN(L27,Assumptions!$B$8),IF(D27="orbit",L27*M27/(2*PI())*R27,IF(D27="boomerang",2,IF(D27="aura",IF(Assumptions!$B$10=1,R27/Assumptions!$B$7,1),IF(D27="trail",Assumptions!$B$9*R27/Assumptions!$B$7,1))))) -> 0.66845076 | T27: =Q27/R27 -> 80 | U27: =Q27/S27 -> 59.83986 | V27: =IF(D27="cone",G27*L27/N27,IF(D27="orbit",G27*L27*M27/(2*PI()),IF(D27="boomerang",G27*2/N27,IF(D27="projectile",G27*L27/N27,IF(D27="trail",G27*Assumptions!$B$9/0.5,G27/N27))))) -> 53.476061 | W27: =IF(V27=0,"",T27/V27) -> 1.4959965 | X27: =R27/N27 -> 1.9230769 | Y27: =IF(D27="aura",IF(R27>Assumptions!$B$11,"ticks needed","pulse ok"),"")
A28: wing-attack | B28: Wing Attack | C28: flying | D28: melee | E28: Melee | F28: physical | G28: 60 | H28: 35 | I28: 100 | N28: 0.55 | O28: =IF(AND(J28<>"",K28<>""),(J28+K28)/2,1) -> 1 | P28: =G28*IF(I28="",100,I28)/100 -> 60 | Q28: =P28*O28 -> 60 | R28: =Assumptions!$B$4*(Assumptions!$B$5/H28)^Assumptions!$B$6 -> 0.5 | S28: =IF(D28="cone",MIN(L28,Assumptions!$B$8),IF(D28="orbit",L28*M28/(2*PI())*R28,IF(D28="boomerang",2,IF(D28="aura",IF(Assumptions!$B$10=1,R28/Assumptions!$B$7,1),IF(D28="trail",Assumptions!$B$9*R28/Assumptions!$B$7,1))))) -> 1 | T28: =Q28/R28 -> 120 | U28: =Q28/S28 -> 60 | V28: =IF(D28="cone",G28*L28/N28,IF(D28="orbit",G28*L28*M28/(2*PI()),IF(D28="boomerang",G28*2/N28,IF(D28="projectile",G28*L28/N28,IF(D28="trail",G28*Assumptions!$B$9/0.5,G28/N28))))) -> 109.09091 | W28: =IF(V28=0,"",T28/V28) -> 1.1 | X28: =R28/N28 -> 0.90909091 | Y28: =IF(D28="aura",IF(R28>Assumptions!$B$11,"ticks needed","pulse ok"),"")
A29: body-slam | B29: Body Slam | C29: normal | D29: melee | E29: Melee | F29: physical | G29: 85 | H29: 15 | I29: 100 | N29: 0.95 | O29: =IF(AND(J29<>"",K29<>""),(J29+K29)/2,1) -> 1 | P29: =G29*IF(I29="",100,I29)/100 -> 85 | Q29: =P29*O29 -> 85 | R29: =Assumptions!$B$4*(Assumptions!$B$5/H29)^Assumptions!$B$6 -> 1.1666667 | S29: =IF(D29="cone",MIN(L29,Assumptions!$B$8),IF(D29="orbit",L29*M29/(2*PI())*R29,IF(D29="boomerang",2,IF(D29="aura",IF(Assumptions!$B$10=1,R29/Assumptions!$B$7,1),IF(D29="trail",Assumptions!$B$9*R29/Assumptions!$B$7,1))))) -> 1 | T29: =Q29/R29 -> 72.857143 | U29: =Q29/S29 -> 85 | V29: =IF(D29="cone",G29*L29/N29,IF(D29="orbit",G29*L29*M29/(2*PI()),IF(D29="boomerang",G29*2/N29,IF(D29="projectile",G29*L29/N29,IF(D29="trail",G29*Assumptions!$B$9/0.5,G29/N29))))) -> 89.473684 | W29: =IF(V29=0,"",T29/V29) -> 0.81428571 | X29: =R29/N29 -> 1.2280702 | Y29: =IF(D29="aura",IF(R29>Assumptions!$B$11,"ticks needed","pulse ok"),"")
A30: hyper-voice | B30: Hyper Voice | C30: normal | D30: nova | E30: Burst | F30: special | G30: 90 | H30: 10 | I30: 100 | L30: 9 | N30: 1.15 | O30: =IF(AND(J30<>"",K30<>""),(J30+K30)/2,1) -> 1 | P30: =G30*IF(I30="",100,I30)/100 -> 90 | Q30: =P30*O30 -> 90 | R30: =Assumptions!$B$4*(Assumptions!$B$5/H30)^Assumptions!$B$6 -> 1.75 | S30: =IF(D30="cone",MIN(L30,Assumptions!$B$8),IF(D30="orbit",L30*M30/(2*PI())*R30,IF(D30="boomerang",2,IF(D30="aura",IF(Assumptions!$B$10=1,R30/Assumptions!$B$7,1),IF(D30="trail",Assumptions!$B$9*R30/Assumptions!$B$7,1))))) -> 1 | T30: =Q30/R30 -> 51.428571 | U30: =Q30/S30 -> 90 | V30: =IF(D30="cone",G30*L30/N30,IF(D30="orbit",G30*L30*M30/(2*PI()),IF(D30="boomerang",G30*2/N30,IF(D30="projectile",G30*L30/N30,IF(D30="trail",G30*Assumptions!$B$9/0.5,G30/N30))))) -> 78.26087 | W30: =IF(V30=0,"",T30/V30) -> 0.65714286 | X30: =R30/N30 -> 1.5217391 | Y30: =IF(D30="aura",IF(R30>Assumptions!$B$11,"ticks needed","pulse ok"),"")
A31: poison-sting | B31: Poison Sting | C31: poison | D31: projectile | E31: Projectile | F31: physical | G31: 15 | H31: 35 | I31: 100 | L31: 1 | N31: 0.34 | O31: =IF(AND(J31<>"",K31<>""),(J31+K31)/2,1) -> 1 | P31: =G31*IF(I31="",100,I31)/100 -> 15 | Q31: =P31*O31 -> 15 | R31: =Assumptions!$B$4*(Assumptions!$B$5/H31)^Assumptions!$B$6 -> 0.5 | S31: =IF(D31="cone",MIN(L31,Assumptions!$B$8),IF(D31="orbit",L31*M31/(2*PI())*R31,IF(D31="boomerang",2,IF(D31="aura",IF(Assumptions!$B$10=1,R31/Assumptions!$B$7,1),IF(D31="trail",Assumptions!$B$9*R31/Assumptions!$B$7,1))))) -> 1 | T31: =Q31/R31 -> 30 | U31: =Q31/S31 -> 15 | V31: =IF(D31="cone",G31*L31/N31,IF(D31="orbit",G31*L31*M31/(2*PI()),IF(D31="boomerang",G31*2/N31,IF(D31="projectile",G31*L31/N31,IF(D31="trail",G31*Assumptions!$B$9/0.5,G31/N31))))) -> 44.117647 | W31: =IF(V31=0,"",T31/V31) -> 0.68 | X31: =R31/N31 -> 1.4705882 | Y31: =IF(D31="aura",IF(R31>Assumptions!$B$11,"ticks needed","pulse ok"),"")
A32: toxic | B32: Toxic | C32: poison | D32: trail | E32: Trail | F32: status | G32: 0 | H32: 10 | I32: 90 | N32: 0.3 | O32: =IF(AND(J32<>"",K32<>""),(J32+K32)/2,1) -> 1 | P32: =G32*IF(I32="",100,I32)/100 -> 0 | Q32: =P32*O32 -> 0 | R32: =Assumptions!$B$4*(Assumptions!$B$5/H32)^Assumptions!$B$6 -> 1.75 | S32: =IF(D32="cone",MIN(L32,Assumptions!$B$8),IF(D32="orbit",L32*M32/(2*PI())*R32,IF(D32="boomerang",2,IF(D32="aura",IF(Assumptions!$B$10=1,R32/Assumptions!$B$7,1),IF(D32="trail",Assumptions!$B$9*R32/Assumptions!$B$7,1))))) -> 7 | T32: =Q32/R32 -> 0 | U32: =Q32/S32 -> 0 | V32: =IF(D32="cone",G32*L32/N32,IF(D32="orbit",G32*L32*M32/(2*PI()),IF(D32="boomerang",G32*2/N32,IF(D32="projectile",G32*L32/N32,IF(D32="trail",G32*Assumptions!$B$9/0.5,G32/N32))))) -> 0 | W32: =IF(V32=0,"",T32/V32) | X32: =R32/N32 -> 5.8333333 | Y32: =IF(D32="aura",IF(R32>Assumptions!$B$11,"ticks needed","pulse ok"),"") | Z32: two clocks today: cd = puddle spacing, puddle ticks every 0.5 s at full damage; see TRAIL_OVERLAP
A33: bulldoze | B33: Bulldoze | C33: ground | D33: aura | E33: Aura | F33: physical | G33: 60 | H33: 20 | I33: 100 | N33: 0.7 | O33: =IF(AND(J33<>"",K33<>""),(J33+K33)/2,1) -> 1 | P33: =G33*IF(I33="",100,I33)/100 -> 60 | Q33: =P33*O33 -> 60 | R33: =Assumptions!$B$4*(Assumptions!$B$5/H33)^Assumptions!$B$6 -> 0.875 | S33: =IF(D33="cone",MIN(L33,Assumptions!$B$8),IF(D33="orbit",L33*M33/(2*PI())*R33,IF(D33="boomerang",2,IF(D33="aura",IF(Assumptions!$B$10=1,R33/Assumptions!$B$7,1),IF(D33="trail",Assumptions!$B$9*R33/Assumptions!$B$7,1))))) -> 1.75 | T33: =Q33/R33 -> 68.571429 | U33: =Q33/S33 -> 34.285714 | V33: =IF(D33="cone",G33*L33/N33,IF(D33="orbit",G33*L33*M33/(2*PI()),IF(D33="boomerang",G33*2/N33,IF(D33="projectile",G33*L33/N33,IF(D33="trail",G33*Assumptions!$B$9/0.5,G33/N33))))) -> 85.714286 | W33: =IF(V33=0,"",T33/V33) -> 0.8 | X33: =R33/N33 -> 1.25 | Y33: =IF(D33="aura",IF(R33>Assumptions!$B$11,"ticks needed","pulse ok"),"") -> ticks needed
A34: bug-bite | B34: Bug Bite | C34: bug | D34: melee | E34: Melee | F34: physical | G34: 60 | H34: 20 | I34: 100 | N34: 0.42 | O34: =IF(AND(J34<>"",K34<>""),(J34+K34)/2,1) -> 1 | P34: =G34*IF(I34="",100,I34)/100 -> 60 | Q34: =P34*O34 -> 60 | R34: =Assumptions!$B$4*(Assumptions!$B$5/H34)^Assumptions!$B$6 -> 0.875 | S34: =IF(D34="cone",MIN(L34,Assumptions!$B$8),IF(D34="orbit",L34*M34/(2*PI())*R34,IF(D34="boomerang",2,IF(D34="aura",IF(Assumptions!$B$10=1,R34/Assumptions!$B$7,1),IF(D34="trail",Assumptions!$B$9*R34/Assumptions!$B$7,1))))) -> 1 | T34: =Q34/R34 -> 68.571429 | U34: =Q34/S34 -> 60 | V34: =IF(D34="cone",G34*L34/N34,IF(D34="orbit",G34*L34*M34/(2*PI()),IF(D34="boomerang",G34*2/N34,IF(D34="projectile",G34*L34/N34,IF(D34="trail",G34*Assumptions!$B$9/0.5,G34/N34))))) -> 142.85714 | W34: =IF(V34=0,"",T34/V34) -> 0.48 | X34: =R34/N34 -> 2.0833333 | Y34: =IF(D34="aura",IF(R34>Assumptions!$B$11,"ticks needed","pulse ok"),"")
A35: string-shot | B35: String Shot | C35: bug | D35: mine | E35: Mines | F35: status | G35: 0 | H35: 40 | I35: 95 | L35: 2 | N35: 1.1 | O35: =IF(AND(J35<>"",K35<>""),(J35+K35)/2,1) -> 1 | P35: =G35*IF(I35="",100,I35)/100 -> 0 | Q35: =P35*O35 -> 0 | R35: =Assumptions!$B$4*(Assumptions!$B$5/H35)^Assumptions!$B$6 -> 0.4375 | S35: =IF(D35="cone",MIN(L35,Assumptions!$B$8),IF(D35="orbit",L35*M35/(2*PI())*R35,IF(D35="boomerang",2,IF(D35="aura",IF(Assumptions!$B$10=1,R35/Assumptions!$B$7,1),IF(D35="trail",Assumptions!$B$9*R35/Assumptions!$B$7,1))))) -> 1 | T35: =Q35/R35 -> 0 | U35: =Q35/S35 -> 0 | V35: =IF(D35="cone",G35*L35/N35,IF(D35="orbit",G35*L35*M35/(2*PI()),IF(D35="boomerang",G35*2/N35,IF(D35="projectile",G35*L35/N35,IF(D35="trail",G35*Assumptions!$B$9/0.5,G35/N35))))) -> 0 | W35: =IF(V35=0,"",T35/V35) | X35: =R35/N35 -> 0.39772727 | Y35: =IF(D35="aura",IF(R35>Assumptions!$B$11,"ticks needed","pulse ok"),"") | Z35: power 0 in game data: status or fixed damage, belongs to the status rework
A36: bug-buzz | B36: Bug Buzz | C36: bug | D36: aura | E36: Aura | F36: special | G36: 90 | H36: 10 | I36: 100 | N36: 0.45 | O36: =IF(AND(J36<>"",K36<>""),(J36+K36)/2,1) -> 1 | P36: =G36*IF(I36="",100,I36)/100 -> 90 | Q36: =P36*O36 -> 90 | R36: =Assumptions!$B$4*(Assumptions!$B$5/H36)^Assumptions!$B$6 -> 1.75 | S36: =IF(D36="cone",MIN(L36,Assumptions!$B$8),IF(D36="orbit",L36*M36/(2*PI())*R36,IF(D36="boomerang",2,IF(D36="aura",IF(Assumptions!$B$10=1,R36/Assumptions!$B$7,1),IF(D36="trail",Assumptions!$B$9*R36/Assumptions!$B$7,1))))) -> 3.5 | T36: =Q36/R36 -> 51.428571 | U36: =Q36/S36 -> 25.714286 | V36: =IF(D36="cone",G36*L36/N36,IF(D36="orbit",G36*L36*M36/(2*PI()),IF(D36="boomerang",G36*2/N36,IF(D36="projectile",G36*L36/N36,IF(D36="trail",G36*Assumptions!$B$9/0.5,G36/N36))))) -> 200 | W36: =IF(V36=0,"",T36/V36) -> 0.25714286 | X36: =R36/N36 -> 3.8888889 | Y36: =IF(D36="aura",IF(R36>Assumptions!$B$11,"ticks needed","pulse ok"),"") -> ticks needed
A37: rock-throw | B37: Rock Throw | C37: rock | D37: projectile | E37: Projectile | F37: physical | G37: 50 | H37: 15 | I37: 90 | L37: 1 | N37: 0.7 | O37: =IF(AND(J37<>"",K37<>""),(J37+K37)/2,1) -> 1 | P37: =G37*IF(I37="",100,I37)/100 -> 45 | Q37: =P37*O37 -> 45 | R37: =Assumptions!$B$4*(Assumptions!$B$5/H37)^Assumptions!$B$6 -> 1.1666667 | S37: =IF(D37="cone",MIN(L37,Assumptions!$B$8),IF(D37="orbit",L37*M37/(2*PI())*R37,IF(D37="boomerang",2,IF(D37="aura",IF(Assumptions!$B$10=1,R37/Assumptions!$B$7,1),IF(D37="trail",Assumptions!$B$9*R37/Assumptions!$B$7,1))))) -> 1 | T37: =Q37/R37 -> 38.571429 | U37: =Q37/S37 -> 45 | V37: =IF(D37="cone",G37*L37/N37,IF(D37="orbit",G37*L37*M37/(2*PI()),IF(D37="boomerang",G37*2/N37,IF(D37="projectile",G37*L37/N37,IF(D37="trail",G37*Assumptions!$B$9/0.5,G37/N37))))) -> 71.428571 | W37: =IF(V37=0,"",T37/V37) -> 0.54 | X37: =R37/N37 -> 1.6666667 | Y37: =IF(D37="aura",IF(R37>Assumptions!$B$11,"ticks needed","pulse ok"),"")
A38: rock-slide | B38: Rock Slide | C38: rock | D38: meteor | E38: Meteors | F38: physical | G38: 75 | H38: 10 | I38: 90 | L38: 3 | N38: 1.3 | O38: =IF(AND(J38<>"",K38<>""),(J38+K38)/2,1) -> 1 | P38: =G38*IF(I38="",100,I38)/100 -> 67.5 | Q38: =P38*O38 -> 67.5 | R38: =Assumptions!$B$4*(Assumptions!$B$5/H38)^Assumptions!$B$6 -> 1.75 | S38: =IF(D38="cone",MIN(L38,Assumptions!$B$8),IF(D38="orbit",L38*M38/(2*PI())*R38,IF(D38="boomerang",2,IF(D38="aura",IF(Assumptions!$B$10=1,R38/Assumptions!$B$7,1),IF(D38="trail",Assumptions!$B$9*R38/Assumptions!$B$7,1))))) -> 1 | T38: =Q38/R38 -> 38.571429 | U38: =Q38/S38 -> 67.5 | V38: =IF(D38="cone",G38*L38/N38,IF(D38="orbit",G38*L38*M38/(2*PI()),IF(D38="boomerang",G38*2/N38,IF(D38="projectile",G38*L38/N38,IF(D38="trail",G38*Assumptions!$B$9/0.5,G38/N38))))) -> 57.692308 | W38: =IF(V38=0,"",T38/V38) -> 0.66857143 | X38: =R38/N38 -> 1.3461538 | Y38: =IF(D38="aura",IF(R38>Assumptions!$B$11,"ticks needed","pulse ok"),"")
A39: ice-beam | B39: Ice Beam | C39: ice | D39: beam | E39: Beam | F39: special | G39: 90 | H39: 10 | I39: 100 | N39: 1.1 | O39: =IF(AND(J39<>"",K39<>""),(J39+K39)/2,1) -> 1 | P39: =G39*IF(I39="",100,I39)/100 -> 90 | Q39: =P39*O39 -> 90 | R39: =Assumptions!$B$4*(Assumptions!$B$5/H39)^Assumptions!$B$6 -> 1.75 | S39: =IF(D39="cone",MIN(L39,Assumptions!$B$8),IF(D39="orbit",L39*M39/(2*PI())*R39,IF(D39="boomerang",2,IF(D39="aura",IF(Assumptions!$B$10=1,R39/Assumptions!$B$7,1),IF(D39="trail",Assumptions!$B$9*R39/Assumptions!$B$7,1))))) -> 1 | T39: =Q39/R39 -> 51.428571 | U39: =Q39/S39 -> 90 | V39: =IF(D39="cone",G39*L39/N39,IF(D39="orbit",G39*L39*M39/(2*PI()),IF(D39="boomerang",G39*2/N39,IF(D39="projectile",G39*L39/N39,IF(D39="trail",G39*Assumptions!$B$9/0.5,G39/N39))))) -> 81.818182 | W39: =IF(V39=0,"",T39/V39) -> 0.62857143 | X39: =R39/N39 -> 1.5909091 | Y39: =IF(D39="aura",IF(R39>Assumptions!$B$11,"ticks needed","pulse ok"),"")
A40: powder-snow | B40: Powder Snow | C40: ice | D40: aura | E40: Aura | F40: special | G40: 40 | H40: 25 | I40: 100 | N40: 0.55 | O40: =IF(AND(J40<>"",K40<>""),(J40+K40)/2,1) -> 1 | P40: =G40*IF(I40="",100,I40)/100 -> 40 | Q40: =P40*O40 -> 40 | R40: =Assumptions!$B$4*(Assumptions!$B$5/H40)^Assumptions!$B$6 -> 0.7 | S40: =IF(D40="cone",MIN(L40,Assumptions!$B$8),IF(D40="orbit",L40*M40/(2*PI())*R40,IF(D40="boomerang",2,IF(D40="aura",IF(Assumptions!$B$10=1,R40/Assumptions!$B$7,1),IF(D40="trail",Assumptions!$B$9*R40/Assumptions!$B$7,1))))) -> 1.4 | T40: =Q40/R40 -> 57.142857 | U40: =Q40/S40 -> 28.571429 | V40: =IF(D40="cone",G40*L40/N40,IF(D40="orbit",G40*L40*M40/(2*PI()),IF(D40="boomerang",G40*2/N40,IF(D40="projectile",G40*L40/N40,IF(D40="trail",G40*Assumptions!$B$9/0.5,G40/N40))))) -> 72.727273 | W40: =IF(V40=0,"",T40/V40) -> 0.78571429 | X40: =R40/N40 -> 1.2727273 | Y40: =IF(D40="aura",IF(R40>Assumptions!$B$11,"ticks needed","pulse ok"),"") -> pulse ok
...

Sheet By kind
A1: Game kind | B1: Workbook kind | C1: Moves | D1: Moves with power | E1: Avg new cd (s) | F1: Avg budget | G1: Avg new / current | H1: Min new / current | I1: Max new / current
A2: melee | B2: Melee | C2: =COUNTIF(Moves!$D$2:$D$65,A2) -> 9 | D2: =COUNTIFS(Moves!$D$2:$D$65,A2,Moves!$G$2:$G$65,">0") -> 9 | E2: =AVERAGEIF(Moves!$D$2:$D$65,A2,Moves!$R$2:$R$65) -> 0.69166667 | F2: =IF(D2=0,"",AVERAGEIFS(Moves!$T$2:$T$65,Moves!$D$2:$D$65,A2,Moves!$G$2:$G$65,">0")) -> 78.809524 | G2: =IF(D2=0,"",AVERAGEIFS(Moves!$W$2:$W$65,Moves!$D$2:$D$65,A2,Moves!$G$2:$G$65,">0")) -> 0.82333333 | H2: =IF(D2=0,"",_xlfn.MINIFS(Moves!$W$2:$W$65,Moves!$D$2:$D$65,A2,Moves!$G$2:$G$65,">0")) -> 0.48 | I2: =IF(D2=0,"",_xlfn.MAXIFS(Moves!$W$2:$W$65,Moves!$D$2:$D$65,A2,Moves!$G$2:$G$65,">0")) -> 1.1
A3: dash | B3: Dash | C3: =COUNTIF(Moves!$D$2:$D$65,A3) -> 2 | D3: =COUNTIFS(Moves!$D$2:$D$65,A3,Moves!$G$2:$G$65,">0") -> 2 | E3: =AVERAGEIF(Moves!$D$2:$D$65,A3,Moves!$R$2:$R$65) -> 0.72916667 | F3: =IF(D3=0,"",AVERAGEIFS(Moves!$T$2:$T$65,Moves!$D$2:$D$65,A3,Moves!$G$2:$G$65,">0")) -> 68.571429 | G3: =IF(D3=0,"",AVERAGEIFS(Moves!$W$2:$W$65,Moves!$D$2:$D$65,A3,Moves!$G$2:$G$65,">0")) -> 1.0714286 | H3: =IF(D3=0,"",_xlfn.MINIFS(Moves!$W$2:$W$65,Moves!$D$2:$D$65,A3,Moves!$G$2:$G$65,">0")) -> 0.85714286 | I3: =IF(D3=0,"",_xlfn.MAXIFS(Moves!$W$2:$W$65,Moves!$D$2:$D$65,A3,Moves!$G$2:$G$65,">0")) -> 1.2857143
A4: projectile | B4: Projectile | C4: =COUNTIF(Moves!$D$2:$D$65,A4) -> 9 | D4: =COUNTIFS(Moves!$D$2:$D$65,A4,Moves!$G$2:$G$65,">0") -> 9 | E4: =AVERAGEIF(Moves!$D$2:$D$65,A4,Moves!$R$2:$R$65) -> 0.80740741 | F4: =IF(D4=0,"",AVERAGEIFS(Moves!$T$2:$T$65,Moves!$D$2:$D$65,A4,Moves!$G$2:$G$65,">0")) -> 61.904762 | G4: =IF(D4=0,"",AVERAGEIFS(Moves!$W$2:$W$65,Moves!$D$2:$D$65,A4,Moves!$G$2:$G$65,">0")) -> 0.67396825 | H4: =IF(D4=0,"",_xlfn.MINIFS(Moves!$W$2:$W$65,Moves!$D$2:$D$65,A4,Moves!$G$2:$G$65,">0")) -> 0.54 | I4: =IF(D4=0,"",_xlfn.MAXIFS(Moves!$W$2:$W$65,Moves!$D$2:$D$65,A4,Moves!$G$2:$G$65,">0")) -> 0.82857143
A5: cone | B5: Spray | C5: =COUNTIF(Moves!$D$2:$D$65,A5) -> 2 | D5: =COUNTIFS(Moves!$D$2:$D$65,A5,Moves!$G$2:$G$65,">0") -> 2 | E5: =AVERAGEIF(Moves!$D$2:$D$65,A5,Moves!$R$2:$R$65) -> 1.0208333 | F5: =IF(D5=0,"",AVERAGEIFS(Moves!$T$2:$T$65,Moves!$D$2:$D$65,A5,Moves!$G$2:$G$65,">0")) -> 75.714286 | G5: =IF(D5=0,"",AVERAGEIFS(Moves!$W$2:$W$65,Moves!$D$2:$D$65,A5,Moves!$G$2:$G$65,">0")) -> 0.095918367 | H5: =IF(D5=0,"",_xlfn.MINIFS(Moves!$W$2:$W$65,Moves!$D$2:$D$65,A5,Moves!$G$2:$G$65,">0")) -> 0.085714286 | I5: =IF(D5=0,"",_xlfn.MAXIFS(Moves!$W$2:$W$65,Moves!$D$2:$D$65,A5,Moves!$G$2:$G$65,">0")) -> 0.10612245
A6: orbit | B6: Orbit | C6: =COUNTIF(Moves!$D$2:$D$65,A6) -> 3 | D6: =COUNTIFS(Moves!$D$2:$D$65,A6,Moves!$G$2:$G$65,">0") -> 3 | E6: =AVERAGEIF(Moves!$D$2:$D$65,A6,Moves!$R$2:$R$65) -> 1.7222222 | F6: =IF(D6=0,"",AVERAGEIFS(Moves!$T$2:$T$65,Moves!$D$2:$D$65,A6,Moves!$G$2:$G$65,">0")) -> 46.309524 | G6: =IF(D6=0,"",AVERAGEIFS(Moves!$W$2:$W$65,Moves!$D$2:$D$65,A6,Moves!$G$2:$G$65,">0")) -> 0.76238283 | H6: =IF(D6=0,"",_xlfn.MINIFS(Moves!$W$2:$W$65,Moves!$D$2:$D$65,A6,Moves!$G$2:$G$65,">0")) -> 0.15535348 | I6: =IF(D6=0,"",_xlfn.MAXIFS(Moves!$W$2:$W$65,Moves!$D$2:$D$65,A6,Moves!$G$2:$G$65,">0")) -> 1.4959965
A7: nova | B7: Burst | C7: =COUNTIF(Moves!$D$2:$D$65,A7) -> 7 | D7: =COUNTIFS(Moves!$D$2:$D$65,A7,Moves!$G$2:$G$65,">0") -> 7 | E7: =AVERAGEIF(Moves!$D$2:$D$65,A7,Moves!$R$2:$R$65) -> 1.25 | F7: =IF(D7=0,"",AVERAGEIFS(Moves!$T$2:$T$65,Moves!$D$2:$D$65,A7,Moves!$G$2:$G$65,">0")) -> 57.459184 | G7: =IF(D7=0,"",AVERAGEIFS(Moves!$W$2:$W$65,Moves!$D$2:$D$65,A7,Moves!$G$2:$G$65,">0")) -> 1.0544898 | H7: =IF(D7=0,"",_xlfn.MINIFS(Moves!$W$2:$W$65,Moves!$D$2:$D$65,A7,Moves!$G$2:$G$65,">0")) -> 0.64285714 | I7: =IF(D7=0,"",_xlfn.MAXIFS(Moves!$W$2:$W$65,Moves!$D$2:$D$65,A7,Moves!$G$2:$G$65,">0")) -> 1.7142857
A8: beam | B8: Beam | C8: =COUNTIF(Moves!$D$2:$D$65,A8) -> 5 | D8: =COUNTIFS(Moves!$D$2:$D$65,A8,Moves!$G$2:$G$65,">0") -> 4 | E8: =AVERAGEIF(Moves!$D$2:$D$65,A8,Moves!$R$2:$R$65) -> 1.925 | F8: =IF(D8=0,"",AVERAGEIFS(Moves!$T$2:$T$65,Moves!$D$2:$D$65,A8,Moves!$G$2:$G$65,">0")) -> 49.142857 | G8: =IF(D8=0,"",AVERAGEIFS(Moves!$W$2:$W$65,Moves!$D$2:$D$65,A8,Moves!$G$2:$G$65,">0")) -> 0.72142857 | H8: =IF(D8=0,"",_xlfn.MINIFS(Moves!$W$2:$W$65,Moves!$D$2:$D$65,A8,Moves!$G$2:$G$65,">0")) -> 0.34285714 | I8: =IF(D8=0,"",_xlfn.MAXIFS(Moves!$W$2:$W$65,Moves!$D$2:$D$65,A8,Moves!$G$2:$G$65,">0")) -> 1.3142857
A9: boomerang | B9: Boomerang | C9: =COUNTIF(Moves!$D$2:$D$65,A9) -> 3 | D9: =COUNTIFS(Moves!$D$2:$D$65,A9,Moves!$G$2:$G$65,">0") -> 3 | E9: =AVERAGEIF(Moves!$D$2:$D$65,A9,Moves!$R$2:$R$65) -> 1.1083333 | F9: =IF(D9=0,"",AVERAGEIFS(Moves!$T$2:$T$65,Moves!$D$2:$D$65,A9,Moves!$G$2:$G$65,">0")) -> 68.690476 | G9: =IF(D9=0,"",AVERAGEIFS(Moves!$W$2:$W$65,Moves!$D$2:$D$65,A9,Moves!$G$2:$G$65,">0")) -> 0.51880952 | H9: =IF(D9=0,"",_xlfn.MINIFS(Moves!$W$2:$W$65,Moves!$D$2:$D$65,A9,Moves!$G$2:$G$65,">0")) -> 0.45714286 | I9: =IF(D9=0,"",_xlfn.MAXIFS(Moves!$W$2:$W$65,Moves!$D$2:$D$65,A9,Moves!$G$2:$G$65,">0")) -> 0.61071429
A10: aura | B10: Aura | C10: =COUNTIF(Moves!$D$2:$D$65,A10) -> 7 | D10: =COUNTIFS(Moves!$D$2:$D$65,A10,Moves!$G$2:$G$65,">0") -> 6 | E10: =AVERAGEIF(Moves!$D$2:$D$65,A10,Moves!$R$2:$R$65) -> 1.3083333 | F10: =IF(D10=0,"",AVERAGEIFS(Moves!$T$2:$T$65,Moves!$D$2:$D$65,A10,Moves!$G$2:$G$65,">0")) -> 55.714286 | G10: =IF(D10=0,"",AVERAGEIFS(Moves!$W$2:$W$65,Moves!$D$2:$D$65,A10,Moves!$G$2:$G$65,">0")) -> 0.47142857 | H10: =IF(D10=0,"",_xlfn.MINIFS(Moves!$W$2:$W$65,Moves!$D$2:$D$65,A10,Moves!$G$2:$G$65,">0")) -> 0.25714286 | I10: =IF(D10=0,"",_xlfn.MAXIFS(Moves!$W$2:$W$65,Moves!$D$2:$D$65,A10,Moves!$G$2:$G$65,">0")) -> 0.8
A11: chain | B11: Chain | C11: =COUNTIF(Moves!$D$2:$D$65,A11) -> 2 | D11: =COUNTIFS(Moves!$D$2:$D$65,A11,Moves!$G$2:$G$65,">0") -> 2 | E11: =AVERAGEIF(Moves!$D$2:$D$65,A11,Moves!$R$2:$R$65) -> 1.4583333 | F11: =IF(D11=0,"",AVERAGEIFS(Moves!$T$2:$T$65,Moves!$D$2:$D$65,A11,Moves!$G$2:$G$65,">0")) -> 57.142857 | G11: =IF(D11=0,"",AVERAGEIFS(Moves!$W$2:$W$65,Moves!$D$2:$D$65,A11,Moves!$G$2:$G$65,">0")) -> 0.66428571 | H11: =IF(D11=0,"",_xlfn.MINIFS(Moves!$W$2:$W$65,Moves!$D$2:$D$65,A11,Moves!$G$2:$G$65,">0")) -> 0.51428571 | I11: =IF(D11=0,"",_xlfn.MAXIFS(Moves!$W$2:$W$65,Moves!$D$2:$D$65,A11,Moves!$G$2:$G$65,">0")) -> 0.81428571
A12: mine | B12: Mines | C12: =COUNTIF(Moves!$D$2:$D$65,A12) -> 3 | D12: =COUNTIFS(Moves!$D$2:$D$65,A12,Moves!$G$2:$G$65,">0") -> 0 | E12: =AVERAGEIF(Moves!$D$2:$D$65,A12,Moves!$R$2:$R$65) -> 0.72916667 | F12: =IF(D12=0,"",AVERAGEIFS(Moves!$T$2:$T$65,Moves!$D$2:$D$65,A12,Moves!$G$2:$G$65,">0")) | G12: =IF(D12=0,"",AVERAGEIFS(Moves!$W$2:$W$65,Moves!$D$2:$D$65,A12,Moves!$G$2:$G$65,">0")) | H12: =IF(D12=0,"",_xlfn.MINIFS(Moves!$W$2:$W$65,Moves!$D$2:$D$65,A12,Moves!$G$2:$G$65,">0")) | I12: =IF(D12=0,"",_xlfn.MAXIFS(Moves!$W$2:$W$65,Moves!$D$2:$D$65,A12,Moves!$G$2:$G$65,">0"))
A13: meteor | B13: Meteors | C13: =COUNTIF(Moves!$D$2:$D$65,A13) -> 3 | D13: =COUNTIFS(Moves!$D$2:$D$65,A13,Moves!$G$2:$G$65,">0") -> 2 | E13: =AVERAGEIF(Moves!$D$2:$D$65,A13,Moves!$R$2:$R$65) -> 1.75 | F13: =IF(D13=0,"",AVERAGEIFS(Moves!$T$2:$T$65,Moves!$D$2:$D$65,A13,Moves!$G$2:$G$65,">0")) -> 42.428571 | G13: =IF(D13=0,"",AVERAGEIFS(Moves!$W$2:$W$65,Moves!$D$2:$D$65,A13,Moves!$G$2:$G$65,">0")) -> 0.69428571 | H13: =IF(D13=0,"",_xlfn.MINIFS(Moves!$W$2:$W$65,Moves!$D$2:$D$65,A13,Moves!$G$2:$G$65,">0")) -> 0.66857143 | I13: =IF(D13=0,"",_xlfn.MAXIFS(Moves!$W$2:$W$65,Moves!$D$2:$D$65,A13,Moves!$G$2:$G$65,">0")) -> 0.72
... A16: buff | B16: Buff | C16: =COUNTIF(Moves!$D$2:$D$65,A16) -> 5 | D16: =COUNTIFS(Moves!$D$2:$D$65,A16,Moves!$G$2:$G$65,">0") -> 0 | E16: =AVERAGEIF(Moves!$D$2:$D$65,A16,Moves!$R$2:$R$65) -> 0.75833333 | F16: =IF(D16=0,"",AVERAGEIFS(Moves!$T$2:$T$65,Moves!$D$2:$D$65,A16,Moves!$G$2:$G$65,">0")) | G16: =IF(D16=0,"",AVERAGEIFS(Moves!$W$2:$W$65,Moves!$D$2:$D$65,A16,Moves!$G$2:$G$65,">0")) | H16: =IF(D16=0,"",_xlfn.MINIFS(Moves!$W$2:$W$65,Moves!$D$2:$D$65,A16,Moves!$G$2:$G$65,">0")) | I16: =IF(D16=0,"",_xlfn.MAXIFS(Moves!$W$2:$W$65,Moves!$D$2:$D$65,A16,Moves!$G$2:$G$65,">0"))
A18: New / current below 1 = the move gets weaker than today, above 1 = stronger. Based on current single-target potential at base config (cones at point blank, orbit target on the ring).

Sheet Notes
A1: How this table works
A2: d = C_cast / E. C_cast = mainline damage of a full use in power units (power x accuracy/100 x hits). E = events one target is expected to take per cast, or per cooldown period for continuous kinds, at the move BASE config.
A3: Power units: the in-game damage is proportional to power for a given attacker/defender, so a power-unit table needs no stat or level assumptions.
A4: Cooldown from PP: cd = ANCHOR_CD x (ANCHOR_PP / PP)^BETA. Budget = C_cast / cd. This is the sustained single-target damage per second the new model gives the move.
A5: Current single-target potential: what the current code can deliver to ONE target at base: cones at point blank (all pellets land), orbs passing a target on the ring once per pass, boomerangs out and back, trail with overlap puddles ticking 0.5 s. It ignores accuracy and uses the current cooldown.
A6: Orbit E = orbs x (omega / 2 pi) x cooldown: passes per cooldown period for a target sitting on the ring (omega is the orbit speed in radians per second). Orbit hits are limited by passes, the current re-hit lock (= cd) is not the binding limit.
A7: Cone E = MIN(pellets, CONE_E). Boomerang E = 2 (out and back). Trail E = TRAIL_OVERLAP x cd / TAU. Aura E = cd / TAU in tick mode, 1 in pulse mode. Everything else E = 1.
A8: Power 0 rows (status moves, fixed-damage Dragon Rage and Night Shade, hazards) are listed for completeness and give 0: the status rework owns them.
A9: Accuracy: blank in PokeAPI (never-miss, status) counts as 100. The game has no miss roll; accuracy is folded into power per the 2026-10-18 decision.
A10: Sources: move stats from js/data/moves.js (game values), PP / accuracy / hits from pokeapi-master/data/v2/csv/moves.csv and move_meta.csv. PP values are current-generation PokeAPI.
